Workbook

Sheet （編集元）
A1: 令和７年度 菊池市立泗水小学校 １年１組 | E1: 担任 ○○ ○○
A3: 担任 ○○ ○○ 男子２２名 女子１８名 計４０名
B5: 児童名 | C5: ふりがな | D5: 性別 | E5: 公簿名 | F5: 公簿名ふりがな
A6: 1 | B6: 秋丸 栞里 | C6: あきまる しおり | D6: 女
A7: 2 | B7: 伊藤 万結 | C7: いとう まゆ | D7: 女
A8: 3 | B8: 岩崎 善躍 | C8: いわさき よう | D8: 男
A9: 4 | B9: 楳田 悠葵 | C9: うめだ ゆうき | D9: 女
A10: 5 | B10: 緒方 心菜 | C10: おがた ここな | D10: 女
A11: 6 | B11: 奥山 樹菜 | C11: おくやま じゅな | D11: 女
A12: 7 | B12: 川口 奨真 | C12: かわぐち しょうま | D12: 男
A13: 8 | B13: 川原 衣千歌 | C13: かわはら いちか | D13: 女
A14: 9 | B14: 北川 倫太良 | C14: きたがわ りんたろう | D14: 男
A15: 10 | B15: 合志 和莉 | C15: こうし あいり | D15: 女
A16: 11 | B16: 小森田 桜道朗 | C16: こもりだ おうじろう | D16: 男
A17: 12 | B17: 酒井 逢糸 | C17: さかい あいと | D17: 男
... A45: 40 | B45: 米満 琴音 | C45: よねみつ ことね | D45: 女
A46: 41
A47: 42

Sheet 名簿①
B1: ='（編集元）'!A1 -> 令和７年度 菊池市立泗水小学校 １年１組 | P1: ='（編集元）'!E1 -> 担任 ○○ ○○
B3: 1 | C3: ='（編集元）'!B6 -> 秋丸 栞里 | D3: ='（編集元）'!C6 -> あきまる しおり
B4: 2 | C4: ='（編集元）'!B7 -> 伊藤 万結 | D4: ='（編集元）'!C7 -> いとう まゆ
B5: 3 | C5: ='（編集元）'!B8 -> 岩崎 善躍 | D5: ='（編集元）'!C8 -> いわさき よう
B6: 4 | C6: ='（編集元）'!B9 -> 楳田 悠葵 | D6: ='（編集元）'!C9 -> うめだ ゆうき
B7: 5 | C7: ='（編集元）'!B10 -> 緒方 心菜 | D7: ='（編集元）'!C10 -> おがた ここな
B8: 6 | C8: ='（編集元）'!B11 -> 奥山 樹菜 | D8: ='（編集元）'!C11 -> おくやま じゅな
B9: 7 | C9: ='（編集元）'!B12 -> 川口 奨真 | D9: ='（編集元）'!C12 -> かわぐち しょうま
B10: 8 | C10: ='（編集元）'!B13 -> 川原 衣千歌 | D10: ='（編集元）'!C13 -> かわはら いちか
B11: 9 | C11: ='（編集元）'!B14 -> 北川 倫太良 | D11: ='（編集元）'!C14 -> きたがわ りんたろう
B12: 10 | C12: ='（編集元）'!B15 -> 合志 和莉 | D12: ='（編集元）'!C15 -> こうし あいり
B13: 11 | C13: ='（編集元）'!B16 -> 小森田 桜道朗 | D13: ='（編集元）'!C16 -> こもりだ おうじろう
B14: 12 | C14: ='（編集元）'!B17 -> 酒井 逢糸 | D14: ='（編集元）'!C17 -> さかい あいと
... B43: 41 | C43: ='（編集元）'!B46 -> 0 | D43: ='（編集元）'!C46 -> 0

Sheet 名簿① (スポテ)
B1: ='（編集元）'!A1 -> 令和７年度 菊池市立泗水小学校 １年１組 | O1: ='（編集元）'!E1 -> 担任 ○○ ○○
D2: 長座体前屈① | E2: 長座体前屈② | F2: 上体起こし | G2: 反復横とび① | H2: 反復横とび② | I2: 立ち幅とび① | J2: 立ち幅とび② | K2: 50ｍ走 | L2: ソフトボール① | M2: ソフトボール② | N2: シャトルラン | O2: 握力右① | P2: 握力右② | Q2: 握力左① | R2: 握力左②
B3: 1 | C3: ='（編集元）'!C6 -> あきまる しおり
B4: 2 | C4: ='（編集元）'!C7 -> いとう まゆ
B5: 3 | C5: ='（編集元）'!C8 -> いわさき よう
B6: 4 | C6: ='（編集元）'!C9 -> うめだ ゆうき
B7: 5 | C7: ='（編集元）'!C10 -> おがた ここな
B8: 6 | C8: ='（編集元）'!C11 -> おくやま じゅな
B9: 7 | C9: ='（編集元）'!C12 -> かわぐち しょうま
B10: 8 | C10: ='（編集元）'!C13 -> かわはら いちか
B11: 9 | C11: ='（編集元）'!C14 -> きたがわ りんたろう
B12: 10 | C12: ='（編集元）'!C15 -> こうし あいり
B13: 11 | C13: ='（編集元）'!C16 -> こもりだ おうじろう
B14: 12 | C14: ='（編集元）'!C17 -> さかい あいと
... B43: 41 | C43: ='（編集元）'!C46 -> 0

Sheet 名簿
B1: ='（編集元）'!A1 -> 令和７年度 菊池市立泗水小学校 １年１組 | K1: ='（編集元）'!A3 -> 担任 ○○ ○○ 男子２２名 女子１８名 計４０名
B3: 1 | C3: ='（編集元）'!B6 -> 秋丸 栞里 | D3: ='（編集元）'!C6 -> あきまる しおり | E3: ='（編集元）'!D6 -> 女
B4: 2 | C4: ='（編集元）'!B7 -> 伊藤 万結 | D4: ='（編集元）'!C7 -> いとう まゆ | E4: ='（編集元）'!D7 -> 女
B5: 3 | C5: ='（編集元）'!B8 -> 岩崎 善躍 | D5: ='（編集元）'!C8 -> いわさき よう | E5: ='（編集元）'!D8 -> 男
B6: 4 | C6: ='（編集元）'!B9 -> 楳田 悠葵 | D6: ='（編集元）'!C9 -> うめだ ゆうき | E6: ='（編集元）'!D9 -> 女
B7: 5 | C7: ='（編集元）'!B10 -> 緒方 心菜 | D7: ='（編集元）'!C10 -> おがた ここな | E7: ='（編集元）'!D10 -> 女
B8: 6 | C8: ='（編集元）'!B11 -> 奥山 樹菜 | D8: ='（編集元）'!C11 -> おくやま じゅな | E8: ='（編集元）'!D11 -> 女
B9: 7 | C9: ='（編集元）'!B12 -> 川口 奨真 | D9: ='（編集元）'!C12 -> かわぐち しょうま | E9: ='（編集元）'!D12 -> 男
B10: 8 | C10: ='（編集元）'!B13 -> 川原 衣千歌 | D10: ='（編集元）'!C13 -> かわはら いちか | E10: ='（編集元）'!D13 -> 女
B11: 9 | C11: ='（編集元）'!B14 -> 北川 倫太良 | D11: ='（編集元）'!C14 -> きたがわ りんたろう | E11: ='（編集元）'!D14 -> 男
B12: 10 | C12: ='（編集元）'!B15 -> 合志 和莉 | D12: ='（編集元）'!C15 -> こうし あいり | E12: ='（編集元）'!D15 -> 女
B13: 11 | C13: ='（編集元）'!B16 -> 小森田 桜道朗 | D13: ='（編集元）'!C16 -> こもりだ おうじろう | E13: ='（編集元）'!D16 -> 男
B14: 12 | C14: ='（編集元）'!B17 -> 酒井 逢糸 | D14: ='（編集元）'!C17 -> さかい あいと | E14: ='（編集元）'!D17 -> 男
... B43: 41 | C43: ='（編集元）'!B46 -> 0 | D43: ='（編集元）'!C46 -> 0 | E43: ='（編集元）'!D46 -> 0

Sheet 名札(A)
A1: 1 | B1: ='（編集元）'!B6 -> 秋丸 栞里
A6: 2 | B6: ='（編集元）'!B7 -> 伊藤 万結
A11: 3 | B11: =名簿!C5 -> 岩崎 善躍
A16: 4 | B16: =名簿!C6 -> 楳田 悠葵
A21: 5 | B21: =名簿!C7 -> 緒方 心菜
A26: 6 | B26: =名簿!C8 -> 奥山 樹菜
A31: 7 | B31: =名簿!C9 -> 川口 奨真
A36: 8 | B36: ='（編集元）'!B13 -> 川原 衣千歌
A41: 9 | B41: ='（編集元）'!B14 -> 北川 倫太良
A46: 10 | B46: ='（編集元）'!B15 -> 合志 和莉
A52: 11 | B52: ='（編集元）'!B16 -> 小森田 桜道朗
A57: 12 | B57: ='（編集元）'!B17 -> 酒井 逢糸
A62: 13 | B62: ='（編集元）'!B18 ->  智也
A67: 14 | B67: ='（編集元）'!B19 -> 坂﨑 稀一
A72: 15 | B72: ='（編集元）'!B20 -> 佐々木 満ちる
A77: 16 | B77: ='（編集元）'!B21 -> 猿渡 結人
A82: 17 | B82: ='（編集元）'!B22 -> 白木 陸斗
A87: 18 | B87: ='（編集元）'!B23 -> 杉山 栞
A92: 19 | B92: ='（編集元）'!B24 -> 園田 優結音
A97: 20 | B97: ='（編集元）'!B25 -> 高野 暁仁
A103: 21 | B103: ='（編集元）'!B26 -> 髙本 善
A108: 22 | B108: ='（編集元）'!B27 -> 田添 源
A113: 23 | B113: ='（編集元）'!B28 -> 刀川 滉生
A118: 24 | B118: ='（編集元）'!B29 -> 田中 塁
A123: 25 | B123: ='（編集元）'!B30 -> 中上 奏汰
A128: 26 | B128: ='（編集元）'!B31 -> 中島 颯佑
A133: 27 | B133: ='（編集元）'!B32 -> 中山 綺心
A138: 28 | B138: ='（編集元）'!B33 -> 野田 純礼
A143: 29 | B143: ='（編集元）'!B34 -> 福田 駈
A148: 30 | B148: ='（編集元）'!B35 -> 裵 日向
A154: 31 | B154: ='（編集元）'!B36 -> 三池 陽
A159: 32 | B159: ='（編集元）'!B37 -> 右田 愛莉
A164: 33 | B164: ='（編集元）'!B38 -> 南 好
A169: 34 | B169: ='（編集元）'!B39 -> 森 蓮生愛
A174: 35 | B174: ='（編集元）'!B40 -> 森本 茉尋
A179: 36 | B179: ='（編集元）'!B41 -> 梁池 維十
A184: 37 | B184: ='（編集元）'!B42 -> 梁池 遥真
A189: 38 | B189: ='（編集元）'!B43 -> 山口 大惺
A194: 39 | B194: ='（編集元）'!B44 -> 山本 大隼
A199: 40 | B199: ='（編集元）'!B45 -> 米満 琴音
...

Sheet なふだ(A)
A1: 1 | B1: ='（編集元）'!C6 -> あきまる しおり
A6: 2 | B6: ='（編集元）'!C7 -> いとう まゆ
A11: 3 | B11: ='（編集元）'!C8 -> いわさき よう
A16: 4 | B16: ='（編集元）'!C9 -> うめだ ゆうき
A21: 5 | B21: ='（編集元）'!C10 -> おがた ここな
A26: 6 | B26: ='（編集元）'!C11 -> おくやま じゅな
A31: 7 | B31: ='（編集元）'!C12 -> かわぐち しょうま
A36: 8 | B36: ='（編集元）'!C13 -> かわはら いちか
A41: 9 | B41: ='（編集元）'!C14 -> きたがわ りんたろう
A46: 10 | B46: ='（編集元）'!C15 -> こうし あいり
A52: 11 | B52: ='（編集元）'!C16 -> こもりだ おうじろう
A57: 12 | B57: ='（編集元）'!C17 -> さかい あいと
A62: 13 | B62: ='（編集元）'!C18 -> さかき ともや
A67: 14 | B67: ='（編集元）'!C19 -> さかざき きいち
A72: 15 | B72: ='（編集元）'!C20 -> ささき みちる
A77: 16 | B77: ='（編集元）'!C21 -> さるわたり ゆいと
A82: 17 | B82: ='（編集元）'!C22 -> しらき りくと
A87: 18 | B87: ='（編集元）'!C23 -> すぎやま しおり
A92: 19 | B92: ='（編集元）'!C24 -> そのだ ゆいね
A97: 20 | B97: ='（編集元）'!C25 -> たかの あきひと
A103: 21 | B103: ='（編集元）'!C26 -> たかもと ぜん
A108: 22 | B108: ='（編集元）'!C27 -> たぞえ げん
A113: 23 | B113: ='（編集元）'!C28 -> たちかわ こうせい
A118: 24 | B118: ='（編集元）'!C29 -> たなか るい
A123: 25 | B123: ='（編集元）'!C30 -> なかがみ そうた
A128: 26 | B128: ='（編集元）'!C31 -> なかしま そうすけ
A133: 27 | B133: ='（編集元）'!C32 -> なかやま きし
A138: 28 | B138: ='（編集元）'!C33 -> のだ すみれ
A143: 29 | B143: ='（編集元）'!C34 -> ふくだ かける
A148: 30 | B148: ='（編集元）'!C35 -> ぺえ ひなた
A154: 31 | B154: ='（編集元）'!C36 -> みいけ ひかり
A159: 32 | B159: ='（編集元）'!C37 -> みぎた あいり
A164: 33 | B164: ='（編集元）'!C38 -> みなみ このみ
A169: 34 | B169: ='（編集元）'!C39 -> もり れいあ
A174: 35 | B174: ='（編集元）'!C40 -> もりもと まひろ
A179: 36 | B179: ='（編集元）'!C41 -> やなち いと
A184: 37 | B184: ='（編集元）'!C42 -> やなち はるま
A189: 38 | B189: ='（編集元）'!C43 -> やまぐち たいせい
A194: 39 | B194: ='（編集元）'!C44 -> やまもと はると
A199: 40 | B199: ='（編集元）'!C45 -> よねみつ ことね
...

Sheet 名札(B)
B1: 1 | C1: ='（編集元）'!B6 -> 秋丸 栞里 | E1: 22 | F1: ='（編集元）'!B27 -> 田添 源
B2: 2 | C2: ='（編集元）'!B7 -> 伊藤 万結 | E2: 23 | F2: ='（編集元）'!B28 -> 刀川 滉生
B3: 3 | C3: ='（編集元）'!B8 -> 岩崎 善躍 | E3: 24 | F3: ='（編集元）'!B29 -> 田中 塁
B4: 4 | C4: ='（編集元）'!B9 -> 楳田 悠葵 | E4: 25 | F4: ='（編集元）'!B30 -> 中上 奏汰
B5: 5 | C5: ='（編集元）'!B10 -> 緒方 心菜 | E5: 26 | F5: ='（編集元）'!B31 -> 中島 颯佑
B6: 6 | C6: ='（編集元）'!B11 -> 奥山 樹菜 | E6: 27 | F6: ='（編集元）'!B32 -> 中山 綺心
B7: 7 | C7: ='（編集元）'!B12 -> 川口 奨真 | E7: 28 | F7: ='（編集元）'!B33 -> 野田 純礼
B8: 8 | C8: ='（編集元）'!B13 -> 川原 衣千歌 | E8: 29 | F8: ='（編集元）'!B34 -> 福田 駈
B9: 9 | C9: ='（編集元）'!B14 -> 北川 倫太良 | E9: 30 | F9: ='（編集元）'!B35 -> 裵 日向
B10: 10 | C10: ='（編集元）'!B15 -> 合志 和莉 | E10: 31 | F10: ='（編集元）'!B36 -> 三池 陽
B11: 11 | C11: ='（編集元）'!B16 -> 小森田 桜道朗 | E11: 32 | F11: ='（編集元）'!B37 -> 右田 愛莉
B12: 12 | C12: ='（編集元）'!B17 -> 酒井 逢糸 | E12: 33 | F12: ='（編集元）'!B38 -> 南 好
... B21: 21 | C21: ='（編集元）'!B26 -> 髙本 善 | E21: 42 | F21: ='（編集元）'!B47 -> 0

Sheet なふだ(B)
B1: 1 | C1: ='（編集元）'!C6 -> あきまる しおり | E1: 22 | F1: ='（編集元）'!C27 -> たぞえ げん
B2: 2 | C2: ='（編集元）'!C7 -> いとう まゆ | E2: 23 | F2: ='（編集元）'!C28 -> たちかわ こうせい
B3: 3 | C3: ='（編集元）'!C8 -> いわさき よう | E3: 24 | F3: ='（編集元）'!C29 -> たなか るい
B4: 4 | C4: ='（編集元）'!C9 -> うめだ ゆうき | E4: 25 | F4: ='（編集元）'!C30 -> なかがみ そうた
B5: 5 | C5: ='（編集元）'!C10 -> おがた ここな | E5: 26 | F5: ='（編集元）'!C31 -> なかしま そうすけ
B6: 6 | C6: ='（編集元）'!C11 -> おくやま じゅな | E6: 27 | F6: ='（編集元）'!C32 -> なかやま きし
B7: 7 | C7: ='（編集元）'!C12 -> かわぐち しょうま | E7: 28 | F7: ='（編集元）'!C33 -> のだ すみれ
B8: 8 | C8: ='（編集元）'!C13 -> かわはら いちか | E8: 29 | F8: ='（編集元）'!C34 -> ふくだ かける
B9: 9 | C9: ='（編集元）'!C14 -> きたがわ りんたろう | E9: 30 | F9: ='（編集元）'!C35 -> ぺえ ひなた
B10: 10 | C10: ='（編集元）'!C15 -> こうし あいり | E10: 31 | F10: ='（編集元）'!C36 -> みいけ ひかり
B11: 11 | C11: ='（編集元）'!C16 -> こもりだ おうじろう | E11: 32 | F11: ='（編集元）'!C37 -> みぎた あいり
B12: 12 | C12: ='（編集元）'!C17 -> さかい あいと | E12: 33 | F12: ='（編集元）'!C38 -> みなみ このみ
... B21: 21 | C21: ='（編集元）'!C26 -> たかもと ぜん | E21: 42 | F21: ='（編集元）'!C47 -> 0

Sheet 黒板
A1: 1 | D1: 2 | G1: 21 | J1: 22
A3: 3 | D3: 4 | G3: 23 | J3: 24
A5: 5 | D5: 6 | G5: 25 | J5: 26
A7: 7 | D7: 8 | G7: 27 | J7: 28
A9: 9 | D9: 10 | G9: 29 | J9: 30
A11: 11 | D11: 12 | G11: 31 | J11: 32
A13: 13 | D13: 14 | G13: 33 | J13: 34
A15: 15 | D15: 16 | G15: 35 | J15: 36
A17: 17 | D17: 18 | G17: 37 | J17: 38
A19: 19 | D19: 20 | G19: 39 | J19: 40
